Workbook

Sheet Tomato Lines
A1: Tomato breeding line evaluation trial Princeton Center 2026 summer
A2: EN | B2: Entries/Lines | C2: Note | D2: Plant number in field | E2: Growth habit | F2: Type | G2: Color | H2: Other notes
A3: 1 | B3: UKYT-25-001 | C3: Breeding Trial | D3: 4 | E3: Indeterminate | F3: grape tomato | G3: pink | H3: supposedly resistance to late blight, some have root knot nematode resistance, fusarium wilt, verticillium wilt and tomato mosaic virus resistance (need to be tested for other disease markers)
A4: 2 | B4: UKYT-25-002 | C4: Breeding Trial | D4: 4 | E4: Indeterminate | F4: grape tomato | G4: orange
A5: 3 | B5: UKYT-25-003 | C5: Breeding Trial | D5: 4 | E5: Indeterminate | F5: grape tomato | G5: purple
A6: 4 | B6: UKYT-25-004 | C6: Breeding Trial | D6: 4 | E6: Indeterminate | F6: grape tomato | G6: yellow with green stripes
A7: 5 | B7: UKYT-25-005 | C7: Breeding Trial | D7: 4 | E7: Indeterminate | F7: grape tomato | G7: yellow
A8: 6 | B8: UKYT-25-006 | C8: Breeding Trial | D8: 4 | E8: Indeterminate | F8: grape tomato | G8: red with green stripes
A9: 7 | B9: UKYT-25-007 | C9: Breeding Trial | D9: 4 | E9: Indeterminate | F9: grape tomato | G9: orange with green stripes
A10: 8 | B10: UKYT-25-008 | C10: Breeding Trial | D10: 4 | E10: Indeterminate | F10: grape tomato | G10: red with green stripes
A11: 9 | B11: UKYT-25-009 | C11: Breeding Trial | D11: 4 | E11: Indeterminate | F11: grape tomato | G11: orange with green stripes
A12: 10 | B12: UKYT-25-010 | C12: Breeding Trial | D12: 4 | E12: Indeterminate | F12: grape tomato | G12: red with green stripes
A13: 11 | B13: UKYT-25-011 | C13: Breeding Trial | D13: 4 | E13: Indeterminate | F13: grape tomato | G13: red with green stripes
A14: 12 | B14: UKYT-25-012 | C14: Breeding Trial | D14: 4 | E14: Indeterminate | F14: grape tomato | G14: orange
A15: 13 | B15: UKYT-25-013 | C15: Breeding Trial | D15: 4 | E15: Indeterminate | F15: grape tomato | G15: red with green stripes
... A19: 17 | B19: UKYT-25-017 | C19: Breeding Trial | D19: 4 | E19: Indeterminate | F19: grape tomato | G19: red with green stripes
A20: 18 | B20: UKYT-26-001 | C20: Breeding Trial | D20: 4 | E20: Determinate | F20: medium fruit size with blocky shape | G20: red | H20: resistance to bacterial wilt, fusarium wilt and root knot nematode
A21: 19 | B21: UKYT-26-006 | C21: Breeding Trial | D21: 4 | E21: Determinate | F21: grape tomato | G21: red | H21: resistance to late blight, TMV and fusarium
A22: 20 | B22: UKYT-26-011 | C22: Breeding Trial | D22: 4 | E22: Indeterminate | F22: large tomatoes | G22: pink | H22: resistance to late blight and possibly other diseases (need to be tested for markers)
A23: 21 | B23: UKYT-26-012 | C23: Breeding Trial | D23: 4 | E23: Indeterminate | F23: large tomatoes | G23: red
A24: 22 | B24: UKYT-26-013 | C24: Breeding Trial | D24: 4 | E24: Indeterminate | F24: large tomatoes | G24: purple
A25: 23 | B25: UKYT-26-014 | C25: Breeding Trial | D25: 4 | E25: Determinate | F25: large tomatoes | G25: pink
A26: 24 | B26: UKYT-26-015 | C26: Breeding Trial | D26: 4 | E26: Indeterminate | F26: grape tomato | G26: orange with green stripes
A27: 25 | B27: UKYT-26-016 | C27: Breeding Trial | D27: 4 | E27: Indeterminate | F27: large tomatoes | G27: pink
A28: 26 | B28: UKYT-26-017 | C28: Breeding Trial | D28: 4 | E28: Determinate | F28: large tomatoes | G28: purple
A29: 27 | B29: UKYT-26-018 | C29: Breeding Trial | D29: 4 | E29: Determinate | F29: large tomatoes | G29: purple
A30: 28 | B30: UKYT-26-019 | C30: Breeding Trial | D30: 4 | E30: Determinate | F30: large tomatoes | G30: yellow, red bicolor
A31: 29 | B31: UKYT-26-020 | C31: Breeding Trial | D31: 4 | E31: Indeterminate | F31: large tomatoes | G31: red
A32: 30 | B32: UKYT-26-021 | C32: Breeding Trial | D32: 4 | E32: Indeterminate | F32: large tomatoes | G32: red with yellow stripes
A33: 31 | B33: UKYT-26-022 | C33: Breeding Trial | D33: 4 | E33: Indeterminate | F33: large tomatoes | G33: purple with green stripes
A34: 32 | B34: UKYT-26-023 | C34: Breeding Trial | D34: 4 | E34: Indeterminate | F34: large tomatoes | G34: red
... A52: 50 | B52: Cherokee Purple | C52: Breeding Trial | D52: 4 | E52: Indeterminate | F52: large tomatoes | G52: purple
A53: 51 | B53: NC 25202G | C53: Hybrid evaluation | D53: 4 | E53: Indeterminate | F53: large tomatoes | G53: red | H53: Need to be tested for disease markers
A54: 52 | B54: NC 25203G | C54: Hybrid evaluation | D54: 4 | E54: Indeterminate | F54: large tomatoes | G54: purple
A55: 53 | B55: NC 25205G | C55: Hybrid evaluation | D55: 4 | E55: Indeterminate | F55: large tomatoes | G55: red
A56: 54 | B56: NC 25207G | C56: Hybrid evaluation | D56: 4 | E56: Indeterminate | F56: large tomatoes | G56: pink
A57: 55 | B57: NC 25208G | C57: Hybrid evaluation | D57: 4 | E57: Indeterminate | F57: large tomatoes | G57: red
A58: 56 | B58: NC 25209G | C58: Hybrid evaluation | D58: 4 | E58: Indeterminate | F58: large tomatoes | G58: pink
A59: 57 | B59: NC 25210G | C59: Hybrid evaluation | D59: 4 | E59: Indeterminate | F59: large tomatoes | G59: red
A60: 58 | B60: NC 25212G | C60: Hybrid evaluation | D60: 4 | E60: Indeterminate | F60: large tomatoes | G60: pink
...

Sheet Layout
A1: Entries/Lines | B1: Fruit/Habit | D1: Entries/Lines | E1: Fruit/Habit | G1: Entries/Lines | H1: Fruit/Habit | J1: Entries/Lines | K1: Fruit/Habit | M1: Entries/Lines | N1: Fruit/Habit
A3: UKYT-25-017 | B3: GR/I | G3: UKYT-26-036 | H3: L/D | M3: NC 25317G | N3: L/D
A4: UKYT-25-016 | B4: GR/I | D4: UKYT-26-031 | E4: L/I | G4: UKYT-26-032 | H4: L/D | J4: NC 25241G | K4: L/I | M4: NC 25315G | N4: L/D
A5: UKYT-25-015 | B5: GR/I | D5: UKYT-26-030 | E5: L/I | G5: UKYT-26-019 | H5: L/D | J5: NC 25240G | K5: L/I | M5: NC 25313G | N5: L/D
A6: UKYT-25-014 | B6: GR/I | D6: UKYT-26-029 | E6: L/I | G6: UKYT-26-018 | H6: L/D | J6: NC 25231G | K6: L/I | M6: NC 25311G | N6: L/D
A7: UKYT-25-013 | B7: GR/I | D7: UKYT-26-028 | E7: L/I | G7: UKYT-26-017 | H7: L/D | J7: NC 25230G | K7: L/I | M7: NC 25306G | N7: L/D
A8: UKYT-25-012 | B8: GR/I | D8: UKYT-26-027 | E8: L/I | G8: UKYT-26-016 | H8: L/D | J8: NC 25217G | K8: L/I | M8: NC 25304G | N8: L/D
A9: UKYT-25-011 | B9: GR/I | D9: UKYT-26-026 | E9: L/I | G9: UKYT-26-015 | H9: L/D | J9: NC 25212G | K9: L/I | M9: NC 25218G | N9: L/D
A10: UKYT-25-010 | B10: GR/I | D10: UKYT-26-025 | E10: L/I | G10: UKYT-26-014 | H10: L/D | J10: NC 25210G | K10: L/I | M10: Mountain Magic | N10: L/D
A11: UKYT-25-009 | B11: GR/I | D11: UKYT-26-024 | E11: L/I | G11: Mountain Fresh Plus | H11: L/D | J11: NC 25209G | K11: L/I | M11: Mountain Girl | N11: L/D
A12: UKYT-25-008 | B12: GR/I | D12: UKYT-26-023 | E12: L/I | G12: UKYT-26-001 | H12: MB/SD | J12: NC 25208G | K12: L/I | M12: Mountain Heritage | N12: L/D
A13: UKYT-25-007 | B13: GR/I | D13: UKYT-26-022 | E13: L/I | G13: UKYT-26-039 | H13: L/I | J13: NC 25207G | K13: L/I | M13: Mountain Gem | N13: L/D
A14: UKYT-25-006 | B14: GR/I | D14: UKYT-26-021 | E14: L/I | G14: UKYT-26-038 | H14: L/I | J14: NC 25205G | K14: L/I | M14: NC 264G | N14: L/I
A15: UKYT-25-005 | B15: GR/I | D15: UKYT-26-020 | E15: L/I | G15: UKYT-26-037 | H15: L/I | J15: NC 25203G | K15: L/I | M15: NC 263G | N15: L/I
... A19: UKYT-25-001 | B19: GR/I | D19: UKYT-26-006 | E19: GL/I | G19: Cherokee Purple | H19: L/I | J19: NC 23706G | K19: L/I | M19: NC 252G | N19: L/I
A21: Row 1 | D21: Row 2 | G21: Row 3 | J21: Row 4 | M21: Row 5
A22: 68 plants | D22: 64 plants | G22: 68 plants | J22: 64 plants | M22: 68 plants
A23: 102 feet long | D23: 96 feet long | G23: 102 feet long | J23: 96 feet long | M23: 102 feet long
A25: Breeding Trial | I25: Hybrid Evaluation
A27: GR | B27: Grape fruit type | G27: 7-ft center-to-center rows | J27: 83 lines | M27: ↑
A28: GL | B28: Globe fruit shape | G28: 18-in plant spacing | J28: 332 plants total | M28: North
A29: MB | B29: Medium size, blocky fruit shape | G29: 36-ft total plot width | J29: 10 metal end posts
A30: I | B30: Indeterminate | G30: 2856 sq. ft. total area | J30: 161 treated 6-ft stakes
A31: SD | B31: Semi-determinate | G31: 0.084 acres
A32: D | B32: Determinate | G32: 0.091 acres with 110-ft plastic

Sheet Record Sheets
A1: UKREC Tomato Advanced Breeding Line Trial - May 14, 2026 Planting
A2: Row | B2: Harvest Date: | F2: Harvest Date: | J2: Harvest Date:
A3: 1 | B3: Marketable | D3: Cull | F3: Marketable | H3: Cull | J3: Marketable | L3: Cull
A4: Entry/Line | B4: Fruit # | C4: Weight | D4: Fruit # | E4: Weight | F4: Fruit # | G4: Weight | H4: Fruit # | I4: Weight | J4: Fruit # | K4: Weight | L4: Fruit # | M4: Weight
A5: UKYT-25-001
A6: UKYT-25-002
A7: UKYT-25-003
A8: UKYT-25-004
A9: UKYT-25-005
A10: UKYT-25-006
A11: UKYT-25-007
A12: UKYT-25-008
A13: UKYT-25-009
A14: UKYT-25-010
A15: UKYT-25-011
A16: UKYT-25-012
... A22: UKREC Tomato Advanced Breeding Line Trial - May 14, 2026 Planting
A23: Row | B23: Harvest Date: | F23: Harvest Date: | J23: Harvest Date:
A24: 2 | B24: Marketable | D24: Cull | F24: Marketable | H24: Cull | J24: Marketable | L24: Cull
A25: Entry/Line | B25: Fruit # | C25: Weight | D25: Fruit # | E25: Weight | F25: Fruit # | G25: Weight | H25: Fruit # | I25: Weight | J25: Fruit # | K25: Weight | L25: Fruit # | M25: Weight
A26: UKYT-26-006
A27: UKYT-26-011
A28: UKYT-26-012
A29: UKYT-26-013
A30: UKYT-26-020
A31: UKYT-26-021
A32: UKYT-26-022
A33: UKYT-26-023
A34: UKYT-26-024
A35: UKYT-26-025
A36: UKYT-26-026
A37: UKYT-26-027
... A43: UKREC Tomato Advanced Breeding Line Trial - May 14, 2026 Planting
A44: Row | B44: Harvest Date: | F44: Harvest Date: | J44: Harvest Date:
A45: 3 | B45: Marketable | D45: Cull | F45: Marketable | H45: Cull | J45: Marketable | L45: Cull
A46: Entry/Line | B46: Fruit # | C46: Weight | D46: Fruit # | E46: Weight | F46: Fruit # | G46: Weight | H46: Fruit # | I46: Weight | J46: Fruit # | K46: Weight | L46: Fruit # | M46: Weight
A47: Cherokee Purple
A48: UKYT-26-033
A49: UKYT-26-034
A50: UKYT-26-035
...

Sheet Mgmnt. Notes
A1: Summer Trial | M1: Summer Notes
A2: 0.091 acre plot area: 5 rows 110-ft long = 550-ft, ≈7-ft bed-to-bed, 36-ft x 110-ft = 3960 sq. ft. | M2: UKYT-26-001, NC25207G, & NC25240G have only 3 plants due to poor germination
A3: 46156 | B3: Planted and 1 cup of 12-48-8 starter fertilizer per plant (1.25 lb in 25 gallon = 5 lb/100) | M3: UKYT-26-017, UKYT-26-028, & UKYT-25-016 had 1 plant break off at base during first stringing
A4: 46171 | B4: Fertilized with double rate, 8.8 lb (4 kg) of calcium nitrate (15.5-0-0) | M4: 1 undersize plant each: UKYT-25-016, UKYT-26-025, UKYT-26-033, UKYT-26-001, NC2541G, NC25230G, NC25217G, NC23926G
B5: Last weeks fertilizer dose missed due to soil saturation | N5: Same plants in UKYT-26-025, NC25241G, NC25217G, NC23926G have foliar disease/distortion?
A6: 46179 | B6: First stringing and pruning/suckering at base of plants | N6: UKYT-26-001 has 1 undersized plant & 1 with foliar disease/distortion?
B7: Fertilized with weekly rate, 4.4 lb (2 kg) of calcium nitrate (15.5-0-0) | M7: 5-day heat 7/1-5 (90.2-95.8°F H, 68.9-74.4°F L) caused flower abortion
B8: Sprayed with of 4 oz Manzate Pro Stick and Cuprofix Ultra Disperse (=2.75 lb/A each) | M8: 5-day heat 7/17-21 (90.2-93.7°F H,73.0-76.2°F L) caused flower abortion
A9: 46185 | B9: Pruning/suckering at base of plants on three rows | M9: 7-day heat 8/10-16 (90.0-95.8°F H, 73.6-78.4°F L) caused flower abortion
A10: 46188 | B10: Pruning/suckering at base of plants on two rows and second stringing all rows | M10: 7-day heat 8/31-9/6 (93.7-100.6°F H, 69.4-72.8°F L) caused flower and fruit abortion
A11: 46189 | B11: Fertilized with weekly rate, 4.4 lb (2 kg) of calcium nitrate (15.5-0-0)
A12: 46190 | B12: Third stringing of canopy along all rows
B13: Sprayed 4 oz (2.75 lb/A) Manzate Pro Stick and 0.5 fl oz (5.5 fl oz/A) Quadris Flowable
A14: 46196 | B14: Fourth stringing of canopy along all rows
A15: 46197 | B15: Fertilized with weekly rate, 4.4 lb (2 kg) of calcium nitrate (15.5-0-0)
A16: 46204 | B16: Fertilized with weekly rate, 4.4 lb (2 kg) of calcium nitrate (15.5-0-0)
A17: 46206 | B17: Sprayed 4 oz (2.75 lb/A) Manzate Pro Stick, 2 fl oz (22 fl oz/A) Fontelis, and 5 fl oz (1.72 qt/A) Sevin XLR Plus
A18: 46217 | B18: 1st harvest from across block, some varieties not yet harvested
B19: Sprayed 4 oz (2.75 lb/A) Manzate Pro Stick, 0.5 fl oz (5.5 fl oz/A) Quadris Flowable, & 1 fl oz Danitol (10.67 fl oz/A)
A20: 46218 | B20: Fertilized with weekly rate, 4.4 lb (2 kg) of calcium nitrate (15.5-0-0)
B21: Double rate not used during harvest, due to risk of calcium goint to excess growth (↑ blossom end rot)
A22: 46225 | B22: 2nd harvest from across block, some varieties not yet harvested
B23: Fifth stringing of canopy along all rows
A24: 46226 | B24: Fertilized with weekly rate, 4.4 lb (2 kg) of calcium nitrate (15.5-0-0)
B25: Sprayed 4 oz Cuprofix Ultra Disperse (2.75 lb/A), 2.5 oz (1.7 lb/A) Dipel DF, & 3 fl oz (2 pt/A) Initiate 720
A26: 46232 | B26: 3rd harvest from across block, all varieties harvested
A27: 46233 | B27: 3rd harvest from across block, all varieties harvested
B28: Sixth stringing of canopy along all rows
B29: Sprayed 4 oz Cuprofix (2.75 lb/A), 2 fl oz (22 fl oz/A) Fontelis, & 5 fl oz Sevin XLR Plus
A30: 46234 | B30: Fertilized with weekly rate, 4.4 lb (2 kg) of calcium nitrate (15.5-0-0)
A31: 46240 | B31: Sprayed 4 oz Cuprofix (2.75 lb/A), 3 fl oz (2 pt/A) Initiate 720, & 1 fl oz (11 fl oz/A) Danitol
A32: 46241 | B32: 4th harvest from across block, all varieties harvested
A33: 46248 | B33: Fertilized with weekly rate, 4.4 lb (2 kg) of calcium nitrate (15.5-0-0)
B34: Sprayed 4 oz Cuprofix (2.75 lb/A), 2 fl oz (22 fl oz/A) Fontelis, 5 fl oz Sevin , & 8 ml Macho (whiteflies)
A35: 46251 | B35: 5th harvest from rows 1 through 3
A36: 46252 | B36: 5th harvest from rows 4 and 5
A37: 46255 | B37: Sprayed 4 oz Cuprofix (2.75 lb/A), 2.5 oz (1.7 lb/A) Dipel; 3 fl oz (2 pt/A) Initiate, & 2 fl oz (1.5 pt/A) Malathion (whiteflies)
A38: 46258 | B38: 6th harvest from across block, all varieties harvested
B39: Fertilized with weekly rate, 4.4 lb (2 kg) of potassium nitrate (13-0-44)
A40: 46262 | B40: Sprayed 4 oz Cuprofix (2.75 lb/A), 2 fl oz (22 fl oz/A) Fontelis, & 5 fl oz Sevin
...

Sheet Cull & Tasting Notes
A1: Row | B1: Entry/Line | C1: Fruit type | D1: Color | E1: Reasons for Culls | G1: Taste Rating | H1: Tasting Notes (7/29-30), 1=poor, 2=fair, 3=good, 4=very good, 5=excellent
A2: 1 | B2: UKYT-25-001 | C2: oval grape | D2: pink | E2: rain cracking, sunburn | G2: 2 | H2: bland but firm, crunchy texture
A3: 1 | B3: UKYT-25-002 | C3: egg shaped grape | D3: orange | E3: rough skin/rain cracking | G3: 2 | H3: bland, very firm, very tough skin
A4: 1 | B4: UKYT-25-003 | C4: oval grape | D4: puple | E4: sun burn | G4: 3 | H4: good but could be better
A5: 1 | B5: UKYT-25-004 | C5: egg shaped grape | D5: yellow w/green stripes | E5: rough skin/rain cracking | G5: 3 | H5: balanced acidity but tough skin
A6: 1 | B6: UKYT-25-005 | C6: pear | D6: yelow | E6: rain cracking, sunburn, blossom end rot | G6: 2 | H6: bland but crunchy, firm texture, fruit detaches/drops easily when picked
A7: 1 | B7: UKYT-25-006 | C7: egg shaped grape | D7: red w/green stripes | E7: rain cracking | G7: 2 | H7: bland but crunchy, firm texture
A8: 1 | B8: UKYT-25-007 | C8: egg shaped grape | D8: orange w/green stripes | E8: rain cracking | G8: 2 | H8: bland but crunchy, firm texture
A9: 1 | B9: UKYT-25-008 | C9: egg shaped grape | D9: red w/green stripes | E9: rough skin/rain cracking | G9: 3 | H9: good, firm, crunchy, but skin is tough
A10: 1 | B10: UKYT-25-009 | C10: egg shaped grape | D10: orange w/green stripes | E10: rough skin/rain cracking, blossom end rot | G10: 2 | H10: bland but crunchy, firm texture
A11: 1 | B11: UKYT-25-010 | C11: egg shaped grape | D11: red w/green stripes | E11: rough skin/rain cracking | G11: 3 | H11: more like traditional cherry flavor, tough skin
A12: 1 | B12: UKYT-25-011 | C12: egg shaped grape | D12: red w/green stripes | E12: rain cracking | G12: 3 | H12: good but could be better
A13: 1 | B13: UKYT-25-012 | C13: egg shaped grape | D13: orange | E13: rough skin, rain cracking | G13: 2 | H13: bland, crunch, firm, tough skin
... A88: 5 | B88: NC 25317G | C88: slicer | D88: pink | E88: rain cracking, misshapen fruit, rot | G88: 2 | H88: bland, but good texture, soft-smooth skin

Sheet Filled Record Sheet
C1: Harvest 1 (7/14, 61 days from planting) | H1: Harvest 2 (7/22, 69 days from planting) | M1: Harvest 3 (7/29, 76 days from planting) | R1: Harvest 4 (8/7, 85 days from planting) | W1: Harvest 5 (8/17, 95 days from planting) | AB1: Harvest 6 (8/24, 102 days from planting) | AG1: Harvest 7 (9/1, 110 days from planting) | AL1: Harvest 8 (9/8, 117 days from planting) | AQ1: Harvest 9 (9/16, 125 days from planting) | AV1: Harvest 10 (9/25, 134 days from planting)
C2: Marketable (lb) | E2: Cull (lb) | H2: Marketable (lb) | J2: Cull (lb) | M2: Marketable (lb) | O2: Cull (lb) | R2: Marketable (lb) | T2: Cull (lb) | W2: Marketable (lb) | Y2: Cull (lb) | AB2: Marketable (lb) | AD2: Cull (lb) | AG2: Marketable (lb) | AI2: Cull (lb) | AL2: Marketable (lb) | AN2: Cull (lb) | AQ2: Marketable (lb) | AS2: Cull (lb) | AV2: Marketable (lb) | AX2: Cull (lb)
A3: Row | B3: Entry/Line | C3: Fruit # | D3: Weight | E3: Fruit # | F3: Weight | H3: Fruit # | I3: Weight | J3: Fruit # | K3: Weight | M3: Fruit # | N3: Weight | O3: Fruit # | P3: Weight | R3: Fruit # | S3: Weight | T3: Fruit # | U3: Weight | W3: Fruit # | X3: Weight | Y3: Fruit # | Z3: Weight | AB3: Fruit # | AC3: Weight | AD3: Fruit # | AE3: Weight | AG3: Fruit # | AH3: Weight | AI3: Fruit # | AJ3: Weight | AL3: Fruit # | AM3: Weight | AN3: Fruit # | AO3: Weight | AQ3: Fruit # | AR3: Weight | AS3: Fruit # | AT3: Weight | AV3: Fruit # | AW3: Weight | AX3: Fruit # | AY3: Weight
A4: 1 | B4: UKYT-25-001 | C4: 22 | D4: 0.76 | E4: 34 | F4: 1.14 | H4: 94 | I4: 2.34 | J4: 26 | K4: 0.62 | M4: 76 | N4: 1.86 | O4: 16 | P4: 0.35 | R4: . | S4: 3.46 | T4: . | U4: 0.68 | W4: . | X4: 1.88 | Y4: . | Z4: 0.58 | AB4: . | AC4: 5.51 | AD4: . | AE4: 0.45 | AG4: . | AH4: 3.63 | AI4: . | AJ4: 0.49 | AL4: . | AM4: 2.46 | AN4: . | AO4: 0.12 | AQ4: . | AR4: 3.65 | AS4: . | AT4: 1.68 | AV4: . | AW4: 1.72 | AX4: . | AY4: 2.63 | BA4: Yellow = grape tomato (fruit # of 3 harvests)
A5: 1 | B5: UKYT-25-002 | C5: 22 | D5: 1.33 | E5: 1 | F5: 0.06 | H5: 32 | I5: 4.87 | J5: 40 | K5: 2.68 | M5: 92 | N5: 3.66 | O5: 16 | P5: 0.62 | R5: . | S5: 3.61 | T5: . | U5: 0.92 | W5: . | X5: 1.03 | Y5: . | Z5: 0.94 | AB5: . | AC5: 3.33 | AD5: . | AE5: 1.13 | AG5: . | AH5: 2.15 | AI5: . | AJ5: 0.94 | AL5: . | AM5: 0.95 | AN5: . | AO5: 0.24 | AQ5: . | AR5: 0.79 | AS5: . | AT5: 1.63 | AV5: . | AW5: 1.14 | AX5: . | AY5: 1.49
A6: 1 | B6: UKYT-25-003 | C6: 31 | D6: 1.16 | E6: 11 | F6: 0.39 | H6: 62 | I6: 2.65 | J6: 24 | K6: 0.71 | M6: 60 | N6: 1.65 | O6: 7 | P6: 0.17 | R6: . | S6: 6.23 | T6: . | U6: 0.62 | W6: . | X6: 2.86 | Y6: . | Z6: 0.74 | AB6: . | AC6: 5.36 | AD6: . | AE6: 0.41 | AG6: . | AH6: 3.74 | AI6: . | AJ6: 0.59 | AL6: . | AM6: 2.08 | AN6: . | AO6: 0.31 | AQ6: . | AR6: 2.83 | AS6: . | AT6: 1.32 | AV6: . | AW6: 2.11 | AX6: . | AY6: 0.56
A7: 1 | B7: UKYT-25-004 | C7: 23 | D7: 1.34 | E7: 7 | F7: 0.4 | H7: 45 | I7: 2.5 | J7: 33 | K7: 1.72 | M7: 114 | N7: 4.36 | O7: 9 | P7: 0.32 | R7: . | S7: 6.09 | T7: . | U7: 0.38 | W7: . | X7: 1.13 | Y7: . | Z7: 0.15 | AB7: . | AC7: 5.31 | AD7: . | AE7: 0.37 | AG7: . | AH7: 3.39 | AI7: . | AJ7: 0.49 | AM7: 0.5 | AN7: . | AO7: 0.11 | AQ7: . | AR7: 1.84 | AS7: . | AT7: 1.83 | AV7: . | AW7: 1.63 | AX7: . | AY7: 1.26
A8: 1 | B8: UKYT-25-005 | C8: 7 | D8: 0.42 | E8: 6 | F8: 0.37 | H8: 36 | I8: 1.73 | J8: 35 | K8: 1.64 | M8: 55 | N8: 2.05 | O8: 22 | P8: 0.67 | R8: . | S8: 4.21 | T8: . | U8: 0.89 | W8: . | X8: 4.84 | Y8: . | Z8: 0.8 | AB8: . | AC8: 3.51 | AD8: . | AE8: 0.09 | AG8: . | AH8: 6.06 | AI8: . | AJ8: 0.29 | AL8: . | AM8: 2.59 | AN8: . | AO8: 0.13 | AQ8: . | AR8: 3.71 | AS8: . | AT8: 0.16 | AV8: . | AW8: 6.64 | AX8: . | AY8: 0.25
A9: 1 | B9: UKYT-25-006 | C9: 26 | D9: 1.36 | E9: 0 | F9: 0 | H9: 52 | I9: 2.78 | J9: 29 | K9: 1.37 | M9: 140 | N9: 5.88 | O9: 28 | P9: 1.03 | R9: . | S9: 4.13 | T9: . | U9: 0.58 | W9: . | X9: 1.55 | Y9: . | Z9: 0.53 | AB9: . | AC9: 2.54 | AD9: . | AE9: 0.3 | AG9: . | AH9: 3.92 | AI9: . | AJ9: 0.12 | AL9: . | AM9: 1.01 | AN9: . | AO9: 0.31 | AQ9: . | AR9: 3.69 | AS9: . | AT9: 1.89 | AV9: . | AW9: 2.78 | AX9: . | AY9: 0.83
A10: 1 | B10: UKYT-25-007 | C10: 36 | D10: 2.35 | E10: 0 | F10: 0 | H10: 81 | I10: 5.13 | J10: 28 | K10: 1.56 | M10: 115 | N10: 5.08 | O10: 5 | P10: 0.19 | R10: . | S10: 3.9 | T10: . | U10: 0.08 | W10: . | X10: 1.35 | Y10: . | Z10: 0.23 | AB10: . | AC10: 5.18 | AD10: . | AE10: 0.38 | AG10: . | AH10: 3.52 | AI10: . | AJ10: 0.81 | AL10: . | AM10: 1.54 | AN10: . | AO10: 0.57 | AQ10: . | AR10: 2.04 | AS10: . | AT10: 2.42 | AV10: . | AW10: 3.19 | AX10: . | AY10: 0.9
A11: 1 | B11: UKYT-25-008 | C11: 18 | D11: 1.25 | E11: 5 | F11: 0.32 | H11: 56 | I11: 3.48 | J11: 29 | K11: 1.81 | M11: 47 | N11: 2.1 | O11: 5 | P11: 0.23 | R11: . | S11: 4.44 | T11: . | U11: 1.19 | W11: . | X11: 0.75 | Y11: . | Z11: 1.14 | AB11: . | AC11: 1.85 | AD11: . | AE11: 0.71 | AG11: . | AH11: 2.88 | AI11: . | AJ11: 2.33 | AL11: . | AM11: 0.77 | AN11: . | AO11: 0.29 | AQ11: . | AR11: 2.08 | AS11: . | AT11: 2.45 | AV11: . | AW11: 0.98 | AX11: . | AY11: 1.71
A12: 1 | B12: UKYT-25-009 | C12: 24 | D12: 1.45 | E12: 3 | F12: 0.11 | H12: 90 | I12: 4.9 | J12: 25 | K12: 1.24 | M12: 49 | N12: 2.03 | O12: 11 | P12: 0.48 | R12: . | S12: 4.59 | T12: . | U12: 0.61 | W12: . | X12: 1.44 | Y12: . | Z12: 0.37 | AB12: . | AC12: 4.35 | AD12: . | AE12: 1.26 | AG12: . | AH12: 1.03 | AI12: . | AJ12: 0.69 | AL12: . | AM12: 0 | AN12: . | AO12: 0 | AQ12: . | AR12: 3.14 | AS12: . | AT12: 2.14 | AV12: . | AW12: 1.27 | AX12: . | AY12: 0.95
A13: 1 | B13: UKYT-25-010 | C13: 29 | D13: 1.63 | E13: 8 | F13: 0.4 | H13: 29 | I13: 1.48 | J13: 45 | K13: 2.44 | M13: 58 | N13: 2.96 | O13: 13 | P13: 0.35 | R13: . | S13: 5.21 | T13: . | U13: 1.34 | W13: . | X13: 1.1 | Y13: . | Z13: 1.14 | AB13: . | AC13: 0.69 | AD13: . | AE13: 0.69 | AG13: . | AH13: 2 | AI13: . | AJ13: 1.16 | AL13: . | AM13: 0.58 | AN13: . | AO13: 0.78 | AQ13: . | AR13: 1.2 | AT13: 1.64 | AV13: . | AW13: 2.17 | AX13: . | AY13: 2.1
A14: 1 | B14: UKYT-25-011 | C14: 40 | D14: 2.13 | E14: 7 | F14: 0.27 | H14: 49 | I14: 2.65 | J14: 34 | K14: 1.34 | M14: 51 | N14: 2.63 | O14: 20 | P14: 0.54 | R14: . | S14: 4.84 | T14: . | U14: 1.71 | W14: . | X14: 1.16 | Y14: . | Z14: 1.01 | AB14: . | AC14: 1.18 | AD14: . | AE14: 0.68 | AG14: . | AH14: 1.22 | AI14: . | AJ14: 1.34 | AL14: . | AM14: 0.62 | AN14: . | AO14: 0.18 | AQ14: . | AR14: 1.74 | AS14: . | AT14: 1.33 | AV14: . | AW14: 2.41 | AX14: . | AY14: 2.41
A15: 1 | B15: UKYT-25-012 | C15: 12 | D15: 0.79 | E15: 0 | F15: 0 | H15: 104 | I15: 5.36 | J15: 9 | K15: 0.44 | M15: 110 | N15: 3.58 | O15: 3 | P15: 0.09 | R15: . | S15: 4.86 | T15: . | U15: 0.01 | W15: . | X15: 8.55 | Y15: . | Z15: 0.26 | AB15: . | AC15: 5.13 | AD15: . | AE15: 0.16 | AG15: . | AH15: 1.69 | AI15: . | AJ15: 1.71 | AL15: . | AM15: 0.91 | AN15: . | AO15: 0.2 | AQ15: . | AR15: 2.62 | AS15: . | AT15: 2.51 | AW15: 3.35 | AX15: . | AY15: 2.18
A16: 1 | B16: UKYT-25-013 | C16: 30 | D16: 1.63 | E16: 7 | F16: 0.31 | H16: 127 | I16: 6.11 | J16: 23 | K16: 0.98 | M16: 119 | N16: 3.61 | O16: 8 | P16: 0.27 | R16: . | S16: 5.62 | T16: . | U16: 0.18 | W16: . | X16: 0.98 | Y16: . | Z16: 0.24 | AB16: . | AC16: 6.13 | AD16: . | AE16: 0.3 | AG16: . | AH16: 3.71 | AI16: . | AJ16: 0.38 | AL16: . | AM16: 0.66 | AN16: . | AO16: 0.12 | AQ16: . | AR16: 3.63 | AS16: . | AT16: 3.44 | AV16: . | AW16: 1.76 | AX16: . | AY16: 0.8
A17: 1 | B17: UKYT-25-014 | C17: 40 | D17: 2.24 | E17: 7 | F17: 0.31 | H17: 176 | I17: 6.48 | J17: 9 | K17: 0.34 | M17: 78 | N17: 2.86 | O17: 9 | P17: 0.33 | R17: . | S17: 6.89 | T17: . | U17: 1.78 | W17: . | X17: 1.56 | Y17: . | Z17: 0.49 | AB17: . | AC17: 4.16 | AD17: . | AE17: 2.31 | AG17: . | AH17: 2.78 | AI17: . | AJ17: 1.1 | AL17: . | AM17: 1.36 | AN17: . | AO17: 0.5 | AQ17: . | AR17: 3.33 | AS17: . | AT17: 2.93 | AV17: . | AW17: 1.6 | AX17: . | AY17: 1.54
A18: 1 | B18: UKYT-25-015 | C18: . | D18: . | E18: . | F18: . | H18: 2 | I18: 1.95 | J18: 8 | K18: 5.45 | M18: 4 | N18: 1.65 | O18: 3 | P18: 2.2 | R18: 1 | S18: 0.61 | T18: 1 | U18: 0.48 | W18: 0 | X18: 0 | Y18: 6 | Z18: 1.95 | AB18: 0 | AC18: 0 | AD18: 1 | AE18: 0.35 | AG18: 0 | AH18: 0 | AI18: 0 | AJ18: 0 | AL18: 3 | AM18: 1.35 | AN18: 1 | AO18: 0.9 | AQ18: 5 | AR18: 3.5 | AS18: 3 | AT18: 1.8 | AV18: 0 | AW18: 0 | AX18: 2 | AY18: 0.35
A19: 1 | B19: UKYT-25-016 | C19: 1 | D19: 0.03 | E19: 7 | F19: 0.22 | H19: 24 | I19: 0.69 | J19: 9 | K19: 0.31 | M19: 17 | N19: 0.34 | O19: 3 | P19: 0.04 | R19: . | S19: 0.76 | T19: . | U19: 0.17 | W19: . | X19: 0.16 | Y19: . | Z19: 0.03 | AB19: . | AC19: 0.31 | AD19: . | AE19: 0.31 | AG19: . | AH19: 1.13 | AI19: . | AJ19: 0.16 | AL19: . | AM19: 0.21 | AN19: . | AO19: 0.04 | AQ19: . | AR19: 0.89 | AS19: . | AT19: 0.64 | AV19: . | AW19: 4.61 | AX19: . | AY19: 0.94
A20: 1 | B20: UKYT-25-017 | C20: 18 | D20: 1.28 | E20: 7 | F20: 0.39 | H20: 77 | I20: 5.36 | J20: 20 | K20: 1.09 | M20: 26 | N20: 0.89 | O20: 0 | P20: 0 | R20: . | S20: 7.29 | T20: . | U20: 0.81 | W20: . | X20: 3 | Y20: . | Z20: 0.85 | AB20: . | AC20: 2.05 | AD20: . | AE20: 1.61 | AG20: . | AH20: 3.31 | AI20: . | AJ20: 0.62 | AL20: . | AM20: 2.08 | AN20: . | AO20: 0.18 | AQ20: . | AR20: 4.28 | AS20: . | AT20: 2.09 | AV20: . | AW20: 3.93 | AX20: . | AY20: 1.69
A22: 2 | B22: UKYT-26-006 | C22: 39 | D22: 1.95 | E22: 11 | F22: 0.55 | H22: 151 | I22: 6.63 | J22: 37 | K22: 1.58 | M22: 108 | N22: 3.41 | O22: 7 | P22: 2.12 | R22: . | S22: 1.54 | T22: . | U22: 2.61 | W22: . | X22: 0.56 | Y22: . | Z22: 0.26 | AB22: . | AC22: 1.19 | AD22: . | AE22: 0.55 | AG22: . | AH22: 0.55 | AI22: . | AJ22: 1.01 | AL22: . | AM22: 0.89 | AN22: . | AO22: 0.16 | AQ22: . | AR22: 0.38 | AS22: . | AT22: 0.28 | AV22: . | AW22: 1.86 | AX22: . | AY22: 0.26
A23: 2 | B23: UKYT-26-011 | C23: 0 | D23: 0 | E23: 3 | F23: 3 | H23: 2 | I23: 1.35 | J23: 12 | K23: 11.2 | M23: 1 | N23: 0.65 | O23: 5 | P23: 3.9 | R23: 6 | S23: 2.16 | T23: 6 | U23: 2.08 | W23: 1 | X23: 0.85 | Y23: 5 | Z23: 3.1 | AB23: 1 | AC23: 0.85 | AD23: 0 | AE23: 0 | AG23: 0 | AH23: 0 | AI23: 1 | AJ23: 0.5 | AL23: 5 | AM23: 3.05 | AN23: 7 | AO23: 4 | AQ23: 0 | AR23: 0 | AS23: 2 | AT23: 0.9 | AV23: 2 | AW23: 0.35 | AX23: 5 | AY23: 1.75
A24: 2 | B24: UKYT-26-012 | C24: 3 | D24: 3.35 | E24: 6 | F24: 4.4 | H24: 0 | I24: 0 | J24: 8 | K24: 8.15 | M24: 2 | N24: 1.5 | O24: 4 | P24: 3.35 | R24: 8 | S24: 2.44 | T24: 8 | U24: 2.76 | W24: 2 | X24: 1.75 | Y24: 3 | Z24: 2.35 | AB24: 1 | AC24: 0.7 | AD24: 1 | AE24: 0.7 | AG24: 0 | AH24: 0 | AI24: 0 | AJ24: 0 | AL24: 1 | AM24: 0.15 | AN24: 2 | AO24: 1.25 | AQ24: 3 | AR24: 1.55 | AS24: 0 | AT24: 0 | AV24: 4 | AW24: 2.4 | AX24: 2 | AY24: 0.8
A25: 2 | B25: UKYT-26-013 | C25: 1 | D25: 1.05 | E25: 0 | F25: 0 | H25: 3 | I25: 2.4 | J25: 7 | K25: 6.25 | M25: 1 | N25: 0.65 | O25: 2 | P25: 1.3 | R25: 1 | S25: 0.38 | T25: 9 | U25: 2.58 | W25: 6 | X25: 3.9 | Y25: 4 | Z25: 1.85 | AB25: 12 | AC25: 6.,45 | AD25: 0 | AE25: 0 | AG25: 2 | AH25: 0.75 | AI25: 1 | AJ25: 0.5 | AL25: 5 | AM25: 1.85 | AN25: 2 | AO25: 0.9 | AQ25: 17 | AR25: 6.85 | AS25: 9 | AT25: 3.6 | AV25: 10 | AW25: 3.75 | AX25: 7 | AY25: 1.8
A26: 2 | B26: UKYT-26-020 | C26: . | D26: . | E26: . | F26: . | H26: 1 | I26: 1.05 | J26: 7 | K26: 5.5 | M26: 3 | N26: 1.65 | O26: 2 | P26: 1.85 | R26: 18 | S26: 6.48 | T26: 12 | U26: 4.12 | W26: 0 | X26: 0 | Y26: 5 | Z26: 2.8 | AB26: 0 | AC26: 0 | AD26: 0 | AE26: 0 | AG26: 0 | AH26: 0 | AI26: 1 | AJ26: 0.15 | AL26: 0 | AM26: 0 | AN26: 0 | AO26: 0 | AQ26: 4 | AR26: 2.85 | AS26: 4 | AT26: 1.45 | AV26: 0 | AW26: 0 | AX26: 3 | AY26: 0.85
A27: 2 | B27: UKYT-26-021 | C27: 0 | D27: 0 | E27: 2 | F27: 1.4 | H27: 2 | I27: 0.85 | J27: 8 | K27: 6.9 | M27: 5 | N27: 4.85 | O27: 1 | P27: 1 | R27: 14 | S27: 3.75 | T27: 13 | U27: 4.66 | W27: 2 | X27: 1.45 | Y27: 3 | Z27: 2.25 | AB27: 0 | AC27: 0 | AD27: 2 | AE27: 1.1 | AG27: 0 | AH27: 0 | AI27: 0 | AJ27: 0 | AL27: 0 | AM27: 0 | AN27: 2 | AO27: 1.55 | AQ27: 2 | AR27: 1.55 | AS27: 4 | AT27: 1.5 | AV27: 0 | AW27: 0 | AX27: 6 | AY27: 2.05
A28: 2 | B28: UKYT-26-022 | C28: . | D28: . | E28: . | F28: . | H28: 0 | I28: 0 | J28: 8 | K28: 5.45 | M28: 4 | N28: 2.75 | O28: 2 | P28: 1.2 | R28: 1 | S28: 0.2 | T28: 2 | U28: 0.52 | W28: 1 | X28: 0.65 | Y28: 3 | Z28: 1.55 | AB28: 0 | AC28: 0 | AD28: 4 | AE28: 1.55 | AG28: 0 | AH28: 0 | AI28: 1 | AJ28: 0.45 | AL28: 7 | AM28: 2.85 | AN28: 3 | AO28: 1.45 | AQ28: 8 | AR28: 3.1 | AS28: 12 | AT28: 4 | AV28: 0 | AW28: 0 | AX28: 8 | AY28: 3
A29: 2 | B29: UKYT-26-023 | C29: 1 | D29: 0.8 | E29: 1 | F29: 1.25 | H29: 6 | I29: 4.15 | J29: 10 | K29: 7.65 | M29: 9 | N29: 5.65 | O29: 2 | P29: 1.4 | R29: 24 | S29: 6.8 | T29: 7 | U29: 1.75 | W29: 5 | X29: 3.25 | Y29: 2 | Z29: 1.1 | AB29: 0 | AC29: 0 | AD29: 0 | AE29: 0 | AG29: 2 | AH29: 0.7 | AI29: 0 | AJ29: 0 | AL29: 5 | AM29: 1.8 | AN29: 6 | AO29: 2.3 | AQ29: 13 | AR29: 5.2 | AS29: 8 | AT29: 2.9 | AV29: 4 | AW29: 1.25 | AX29: 5 | AY29: 1.45
A30: 2 | B30: UKYT-26-024 | C30: . | D30: . | E30: . | F30: . | H30: 1 | I30: 0.65 | J30: 12 | K30: 8.9 | M30: 1 | N30: 0.8 | O30: 6 | P30: 5 | R30: . | S30: . | T30: 15 | U30: 4.8 | W30: 1 | X30: 1.25 | Y30: 0 | Z30: 0 | AB30: 0 | AC30: 0 | AD30: 1 | AE30: 0.55 | AG30: 0 | AH30: 0 | AI30: 1 | AJ30: 0.6 | AL30: 0 | AM30: 0 | AN30: 6 | AO30: 3.5 | AQ30: 0 | AR30: 0 | AS30: 7 | AT30: 2.85 | AV30: 0 | AW30: 0 | AX30: 25 | AY30: 9
A31: 2 | B31: UKYT-26-025 | C31: . | D31: . | E31: . | F31: . | H31: 0 | I31: 0 | J31: 7 | K31: 6.35 | M31: 1 | N31: 0.95 | O31: 2 | P31: 1.9 | R31: 7 | S31: 5.35 | T31: 9 | U31: 6.5 | W31: 3 | X31: 0.95 | Y31: 33 | Z31: 0 | AB31: 0 | AC31: 0 | AD31: 1 | AE31: 0.65 | AG31: 3 | AH31: 0.85 | AI31: 1 | AJ31: 0.2 | AL31: 12 | AM31: 5.2 | AN31: 10 | AO31: 4.25 | AQ31: 12 | AR31: 4.45 | AS31: 6 | AT31: 2.6 | AV31: 0 | AW31: 0 | AX31: 3 | AY31: 1.2
A32: 2 | B32: UKYT-26-026 | C32: 0 | D32: 0 | E32: 2 | F32: 2.1 | H32: 0 | I32: 0 | J32: 5 | K32: 3.55 | M32: 4 | N32: 3.2 | O32: 6 | P32: 5.25 | R32: 3 | S32: 2.05 | T32: 15 | U32: 12.35 | W32: 0 | X32: 0 | Y32: 5 | Z32: 2.4 | AB32: 0 | AC32: 0 | AD32: 2 | AE32: 1.4 | AG32: 0 | AH32: 0 | AI32: 1 | AJ32: 0.4 | AL32: 1 | AM32: 0.45 | AN32: 4 | AO32: 1.6 | AQ32: 0 | AR32: 0 | AS32: 11 | AT32: 5 | AV32: 0 | AW32: 0 | AX32: 4 | AY32: 1.1
A33: 2 | B33: UKYT-26-027 | C33: . | D33: . | E33: . | F33: . | H33: 0 | I33: 0 | J33: 6 | K33: 6.85 | M33: 9 | N33: 9.65 | O33: 2 | P33: 1.7 | R33: 12 | S33: 9.05 | T33: 12 | U33: 8.4 | W33: 4 | X33: 3.3 | Y33: 2 | Z33: 2.05 | AB33: 1 | AC33: 0.85 | AD33: 0 | AE33: 0 | AG33: 1 | AH33: 0.8 | AI33: 0 | AJ33: 0 | AL33: 3 | AM33: 1.35 | AN33: 0 | AO33: 0 | AQ33: 2 | AR33: 1.1 | AS33: 4 | AT33: 1.95 | AV33: 3 | AW33: 1.2 | AX33: 9 | AY33: 4.4
A34: 2 | B34: UKYT-26-028 | C34: 3 | D34: 2.2 | E34: 1 | F34: 0.5 | H34: 8 | I34: 5.6 | J34: 5 | K34: 3.9 | M34: 4 | N34: 1.65 | O34: 1 | P34: 0.5 | R34: 16 | S34: 8.95 | T34: 15 | U34: 6.4 | W34: 4 | X34: 1.75 | Y34: 3 | Z34: 1.75 | AB34: 3 | AC34: 2.25 | AD34: 0 | AE34: 0 | AG34: 0 | AH34: 0 | AI34: 1 | AJ34: 0.4 | AL34: 4 | AM34: 1.7 | AN34: 1 | AO34: 0.35 | AQ34: 6 | AR34: 2.3 | AS34: 5 | AT34: 1.9 | AV34: 8 | AW34: 3.85 | AX34: 5 | AY34: 1.6
A35: 2 | B35: UKYT-26-029 | C35: 1 | D35: 0.5 | E35: 2 | F35: 1 | H35: 9 | I35: 3.15 | J35: 5 | K35: 2.45 | M35: 7 | N35: 2.9 | O35: 1 | P35: 0.5 | R35: 42 | S35: 14.75 | T35: 16 | U35: 5.4 | W35: 26 | X35: 8.7 | Y35: 6 | Z35: 2.05 | AB35: 11 | AC35: 2.8 | AD35: 0 | AE35: 0 | AG35: 5 | AH35: 1.35 | AI35: 2 | AJ35: 0.55 | AL35: 8 | AM35: 2.25 | AN35: 25 | AO35: 5.3 | AQ35: 16 | AR35: 3.65 | AS35: 27 | AT35: 5 | AV35: 7 | AW35: 1.7 | AX35: 9 | AY35: 1.35
A36: 2 | B36: UKYT-26-030 | C36: 1 | D36: 0.3 | E36: 7 | F36: 1.7 | H36: 8 | I36: 1.85 | J36: 9 | K36: 2.6 | M36: 21 | N36: 4.35 | O36: 1 | P36: 0.2 | R36: 37 | S36: 8.25 | T36: 34 | U36: 6.5 | W36: 27 | X36: 4.9 | Y36: 3 | Z36: 0.55 | AB36: 6 | AC36: 0.9 | AD36: 4 | AE36: 0.5 | AG36: 3 | AH36: 0.45 | AI36: 21 | AJ36: 1.9 | AL36: 0 | AM36: 0 | AN36: 15 | AO36: 2 | AQ36: 3 | AR36: 0.5 | AS36: 24 | AT36: 2.55 | AV36: 0 | AW36: 0 | AX36: 16 | AY36: 1.15
A37: 2 | B37: UKYT-26-031 | C37: 2 | D37: 0.85 | E37: 3 | F37: 1.3 | H37: 5 | I37: 2.1 | J37: 11 | K37: 4.75 | M37: 23 | N37: 9.55 | O37: 1 | P37: 0.35 | R37: 15 | S37: 6.1 | T37: 22 | U37: 7.2 | W37: 13 | X37: 5.1 | Y37: 5 | Z37: 1.55 | AB37: 7 | AC37: 1.95 | AD37: 4 | AE37: 0.75 | AG37: 7 | AH37: 1.95 | AI37: 5 | AJ37: 1.05 | AL37: 3 | AM37: 0.95 | AN37: 25 | AO37: 4.65 | AQ37: 1 | AR37: 0.1 | AS37: 13 | AT37: 2.65 | AV37: 18 | AW37: 3.1 | AX37: 42 | AY37: 6.2
A39: 3 | B39: Cherokee Purple | C39: 2 | D39: 1.35 | E39: 3 | F39: 2.5 | H39: 2 | I39: 0.9 | J39: 6 | K39: 3.9 | M39: 2 | N39: 1.15 | O39: 2 | P39: 1.5 | R39: 1 | S39: 0.26 | T39: 7 | U39: 2.08 | W39: 0 | X39: 0 | Y39: 3 | Z39: 1.5 | AB39: 0 | AC39: 0 | AD39: 0 | AE39: 0 | AG39: 0 | AH39: 0 | AI39: 1 | AJ39: 0.55 | AL39: 0 | AM39: 0 | AN39: 2 | AO39: 1.35 | AQ39: 0 | AR39: 0 | AS39: 15 | AT39: 8.1 | AV39: 0 | AW39: 0 | AX39: 28 | AY39: 14.1
A40: 3 | B40: UKYT-26-033 | C40: 3 | D40: 1.45 | E40: 0 | F40: 0 | H40: 38 | I40: 9.75 | J40: 14 | K40: 3.55 | M40: 19 | N40: 4.9 | O40: 3 | P40: 1.1 | R40: 15 | S40: 2.04 | T40: 17 | U40: 2.06 | W40: 6 | X40: 1.9 | Y40: 8 | Z40: 2.55 | AB40: 1 | AC40: 0.3 | AD40: 0 | AE40: 0 | AG40: 8 | AH40: 2.3 | AI40: 5 | AJ40: 1.25 | AL40: 10 | AM40: 2.75 | AN40: 7 | AO40: 1.35 | AQ40: 8 | AR40: 1.7 | AS40: 11 | AT40: 1.8 | AV40: 4 | AW40: 0.65 | AX40: 15 | AY40: 3.5
A41: 3 | B41: UKYT-26-034 | C41: 1 | D41: 0.35 | E41: 1 | F41: 0.35 | H41: 13 | I41: 4.2 | J41: 14 | K41: 4.35 | M41: 15 | N41: 5.7 | O41: 1 | P41: 0.55 | R41: 7 | S41: 1.06 | T41: 12 | U41: 1.84 | W41: 6 | X41: 1.9 | Y41: 4 | Z41: 1 | AB41: 0 | AC41: 0 | AD41: 3 | AE41: 0.7 | AG41: 10 | AH41: 2.55 | AI41: 10 | AJ41: 1.95 | AL41: 0 | AM41: 0 | AN41: 13 | AO41: 2.35 | AQ41: 0 | AR41: 0 | AS41: 7 | AT41: 1 | AV41: 5 | AW41: 0.5 | AX41: 3 | AY41: 0.35
A42: 3 | B42: UKYT-26-035 | C42: 0 | D42: 0 | E42: 9 | F42: 2.65 | H42: 5 | I42: 1 | J42: 7 | K42: 1.7 | M42: 14 | N42: 2.8 | O42: 13 | P42: 2.7 | R42: 13 | S42: 1.3 | T42: 51 | U42: 4.32 | W42: 18 | X42: 3.4 | Y42: 12 | Z42: 2.55 | AB42: 4 | AC42: 0.55 | AD42: 7 | AE42: 0.75 | AG42: 0 | AH42: 0 | AI42: 15 | AJ42: 2 | AL42: 18 | AM42: 2.5 | AN42: 30 | AO42: 3.35 | AQ42: 0 | AR42: 0 | AS42: 61 | AT42: 5.45 | AV42: 4 | AW42: 0.4 | AX42: 23 | AY42: 1.9
...

Sheet Marketable Yield
B1: Fruit Number | Q1: Yield (lb) | AF1: Fruit Size (oz)
A2: Entry/Line | B2: Harvest 1 | C2: Harvest 2 | D2: Harvest 3 | E2: Harvest 4 | F2: Harvest 5 | G2: Harvest 6 | H2: Harvest 7 | I2: Harvest 8 | J2: Harvest 9 | K2: Harvest 10 | L2: Total | M2: Average/Harvest | N2: % of All Fruit Harvested | Q2: Harvest 1 | R2: Harvest 2 | S2: Harvest 3 | T2: Harvest 4 | U2: Harvest 5 | V2: Harvest 6 | W2: Harvest 7 | X2: Harvest 8 | Y2: Harvest 9 | Z2: Harvest 10 | AA2: Total | AB2: Average/Harvest | AC2: % of All Fruit Harvested | AF2: Harvest 1 | AG2: Harvest 2 | AH2: Harvest 3 | AI2: Harvest 4 | AJ2: Harvest 5 | AK2: Harvest 6 | AL2: Harvest 7 | AM2: Harvest 8 | AN2: Harvest 9 | AO2: Harvest 10 | AP2: Average
A3: UKYT-25-001 | B3: 22 | C3: 94 | D3: 76 | E3: . | F3: . | G3: . | H3: . | I3: . | J3: . | K3: . | L3: =SUM(B3:K3) -> 192 | M3: =AVERAGE(B3:K3) -> 64 | N3: =(L3/(L3+'Cull Yield'!L3))*100 -> 71.641791 | Q3: 0.76 | R3: 2.34 | S3: 1.86 | T3: 3.46 | U3: 1.88 | V3: 5.51 | W3: 3.63 | X3: 2.46 | Y3: 3.65 | Z3: 1.72 | AA3: =SUM(Q3:Z3) -> 27.27 | AB3: =AVERAGE(Q3:Z3) -> 2.727 | AC3: =(AA3/(AA3+'Cull Yield'!AA3))*100 -> 75.728964 | AF3: =(Q3/B3)*16 -> 0.55272727 | AG3: =(R3/C3)*16 -> 0.39829787 | AH3: =(S3/D3)*16 -> 0.39157895 | AI3: . | AJ3: . | AK3: . | AL3: . | AM3: . | AN3: . | AO3: . | AP3: =AVERAGE(AF3:AO3) -> 0.4475347 | AR3: Yellow = grape tomato (fruit # of 3 harvests)
A4: UKYT-25-002 | B4: 22 | C4: 32 | D4: 92 | E4: . | F4: . | G4: . | H4: . | I4: . | J4: . | K4: . | L4: =SUM(B4:K4) -> 146 | M4: =AVERAGE(B4:K4) -> 48.666667 | N4: =(L4/(L4+'Cull Yield'!L4))*100 -> 71.921182 | Q4: 1.33 | R4: 4.87 | S4: 3.66 | T4: 3.61 | U4: 1.03 | V4: 3.33 | W4: 2.15 | X4: 0.95 | Y4: 0.79 | Z4: 1.14 | AA4: =SUM(Q4:Z4) -> 22.86 | AB4: =AVERAGE(Q4:Z4) -> 2.286 | AC4: =(AA4/(AA4+'Cull Yield'!AA4))*100 -> 68.218442 | AF4: =(Q4/B4)*16 -> 0.96727273 | AG4: =(R4/C4)*16 -> 2.435 | AH4: =(S4/D4)*16 -> 0.63652174 | AI4: . | AJ4: . | AK4: . | AL4: . | AM4: . | AN4: . | AO4: . | AP4: =AVERAGE(AF4:AO4) -> 1.3462648
A5: UKYT-25-003 | B5: 31 | C5: 62 | D5: 60 | E5: . | F5: . | G5: . | H5: . | I5: . | J5: . | K5: . | L5: =SUM(B5:K5) -> 153 | M5: =AVERAGE(B5:K5) -> 51 | N5: =(L5/(L5+'Cull Yield'!L5))*100 -> 78.461538 | Q5: 1.16 | R5: 2.65 | S5: 1.65 | T5: 6.23 | U5: 2.86 | V5: 5.36 | W5: 3.74 | X5: 2.08 | Y5: 2.83 | Z5: 2.11 | AA5: =SUM(Q5:Z5) -> 30.67 | AB5: =AVERAGE(Q5:Z5) -> 3.067 | AC5: =(AA5/(AA5+'Cull Yield'!AA5))*100 -> 84.050425 | AF5: =(Q5/B5)*16 -> 0.59870968 | AG5: =(R5/C5)*16 -> 0.68387097 | AH5: =(S5/D5)*16 -> 0.44 | AI5: . | AJ5: . | AK5: . | AL5: . | AM5: . | AN5: . | AO5: . | AP5: =AVERAGE(AF5:AO5) -> 0.57419355
A6: UKYT-25-004 | B6: 23 | C6: 45 | D6: 114 | E6: . | F6: . | G6: . | H6: . | J6: . | K6: . | L6: =SUM(B6:K6) -> 182 | M6: =AVERAGE(B6:K6) -> 60.666667 | N6: =(L6/(L6+'Cull Yield'!L6))*100 -> 78.787879 | Q6: 1.34 | R6: 2.5 | S6: 4.36 | T6: 6.09 | U6: 1.13 | V6: 5.31 | W6: 3.39 | X6: 0.5 | Y6: 1.84 | Z6: 1.63 | AA6: =SUM(Q6:Z6) -> 28.09 | AB6: =AVERAGE(Q6:Z6) -> 2.809 | AC6: =(AA6/(AA6+'Cull Yield'!AA6))*100 -> 79.982916 | AF6: =(Q6/B6)*16 -> 0.93217391 | AG6: =(R6/C6)*16 -> 0.88888889 | AH6: =(S6/D6)*16 -> 0.61192982 | AI6: . | AJ6: . | AK6: . | AL6: . | AM6: . | AN6: . | AO6: . | AP6: =AVERAGE(AF6:AO6) -> 0.81099754
A7: UKYT-25-005 | B7: 7 | C7: 36 | D7: 55 | E7: . | F7: . | G7: . | H7: . | I7: . | J7: . | K7: . | L7: =SUM(B7:K7) -> 98 | M7: =AVERAGE(B7:K7) -> 32.666667 | N7: =(L7/(L7+'Cull Yield'!L7))*100 -> 60.869565 | Q7: 0.42 | R7: 1.73 | S7: 2.05 | T7: 4.21 | U7: 4.84 | V7: 3.51 | W7: 6.06 | X7: 2.59 | Y7: 3.71 | Z7: 6.64 | AA7: =SUM(Q7:Z7) -> 35.76 | AB7: =AVERAGE(Q7:Z7) -> 3.576 | AC7: =(AA7/(AA7+'Cull Yield'!AA7))*100 -> 87.113276 | AF7: =(Q7/B7)*16 -> 0.96 | AG7: =(R7/C7)*16 -> 0.76888889 | AH7: =(S7/D7)*16 -> 0.59636364 | AI7: . | AJ7: . | AK7: . | AL7: . | AM7: . | AN7: . | AO7: . | AP7: =AVERAGE(AF7:AO7) -> 0.77508418
A8: UKYT-25-006 | B8: 26 | C8: 52 | D8: 140 | E8: . | F8: . | G8: . | H8: . | I8: . | J8: . | K8: . | L8: =SUM(B8:K8) -> 218 | M8: =AVERAGE(B8:K8) -> 72.666667 | N8: =(L8/(L8+'Cull Yield'!L8))*100 -> 79.272727 | Q8: 1.36 | R8: 2.78 | S8: 5.88 | T8: 4.13 | U8: 1.55 | V8: 2.54 | W8: 3.92 | X8: 1.01 | Y8: 3.69 | Z8: 2.78 | AA8: =SUM(Q8:Z8) -> 29.64 | AB8: =AVERAGE(Q8:Z8) -> 2.964 | AC8: =(AA8/(AA8+'Cull Yield'!AA8))*100 -> 80.983607 | AF8: =(Q8/B8)*16 -> 0.83692308 | AG8: =(R8/C8)*16 -> 0.85538462 | AH8: =(S8/D8)*16 -> 0.672 | AI8: . | AJ8: . | AK8: . | AL8: . | AM8: . | AN8: . | AO8: . | AP8: =AVERAGE(AF8:AO8) -> 0.78810256
A9: UKYT-25-007 | B9: 36 | C9: 81 | D9: 115 | E9: . | F9: . | G9: . | H9: . | I9: . | J9: . | K9: . | L9: =SUM(B9:K9) -> 232 | M9: =AVERAGE(B9:K9) -> 77.333333 | N9: =(L9/(L9+'Cull Yield'!L9))*100 -> 87.54717 | Q9: 2.35 | R9: 5.13 | S9: 5.08 | T9: 3.9 | U9: 1.35 | V9: 5.18 | W9: 3.52 | X9: 1.54 | Y9: 2.04 | Z9: 3.19 | AA9: =SUM(Q9:Z9) -> 33.28 | AB9: =AVERAGE(Q9:Z9) -> 3.328 | AC9: =(AA9/(AA9+'Cull Yield'!AA9))*100 -> 82.335477 | AF9: =(Q9/B9)*16 -> 1.0444444 | AG9: =(R9/C9)*16 -> 1.0133333 | AH9: =(S9/D9)*16 -> 0.70678261 | AI9: . | AJ9: . | AK9: . | AL9: . | AM9: . | AN9: . | AO9: . | AP9: =AVERAGE(AF9:AO9) -> 0.92152013
A10: UKYT-25-008 | B10: 18 | C10: 56 | D10: 47 | E10: . | F10: . | G10: . | H10: . | I10: . | J10: . | K10: . | L10: =SUM(B10:K10) -> 121 | M10: =AVERAGE(B10:K10) -> 40.333333 | N10: =(L10/(L10+'Cull Yield'!L10))*100 -> 75.625 | Q10: 1.25 | R10: 3.48 | S10: 2.1 | T10: 4.44 | U10: 0.75 | V10: 1.85 | W10: 2.88 | X10: 0.77 | Y10: 2.08 | Z10: 0.98 | AA10: =SUM(Q10:Z10) -> 20.58 | AB10: =AVERAGE(Q10:Z10) -> 2.058 | AC10: =(AA10/(AA10+'Cull Yield'!AA10))*100 -> 62.820513 | AF10: =(Q10/B10)*16 -> 1.1111111 | AG10: =(R10/C10)*16 -> 0.99428571 | AH10: =(S10/D10)*16 -> 0.71489362 | AI10: . | AJ10: . | AK10: . | AL10: . | AM10: . | AN10: . | AO10: . | AP10: =AVERAGE(AF10:AO10) -> 0.94009681
A11: UKYT-25-009 | B11: 24 | C11: 90 | D11: 49 | E11: . | F11: . | G11: . | H11: . | I11: . | J11: . | K11: . | L11: =SUM(B11:K11) -> 163 | M11: =AVERAGE(B11:K11) -> 54.333333 | N11: =(L11/(L11+'Cull Yield'!L11))*100 -> 80.693069 | Q11: 1.45 | R11: 4.9 | S11: 2.03 | T11: 4.59 | U11: 1.44 | V11: 4.35 | W11: 1.03 | X11: 0 | Y11: 3.14 | Z11: 1.27 | AA11: =SUM(Q11:Z11) -> 24.2 | AB11: =AVERAGE(Q11:Z11) -> 2.42 | AC11: =(AA11/(AA11+'Cull Yield'!AA11))*100 -> 75.50702 | AF11: =(Q11/B11)*16 -> 0.96666667 | AG11: =(R11/C11)*16 -> 0.87111111 | AH11: =(S11/D11)*16 -> 0.66285714 | AI11: . | AJ11: . | AK11: . | AL11: . | AM11: . | AN11: . | AO11: . | AP11: =AVERAGE(AF11:AO11) -> 0.83354497
A12: UKYT-25-010 | B12: 29 | C12: 29 | D12: 58 | E12: . | F12: . | G12: . | H12: . | I12: . | J12: . | K12: . | L12: =SUM(B12:K12) -> 116 | M12: =AVERAGE(B12:K12) -> 38.666667 | N12: =(L12/(L12+'Cull Yield'!L12))*100 -> 63.736264 | Q12: 1.63 | R12: 1.48 | S12: 2.96 | T12: 5.21 | U12: 1.1 | V12: 0.69 | W12: 2 | X12: 0.58 | Y12: 1.2 | Z12: 2.17 | AA12: =SUM(Q12:Z12) -> 19.02 | AB12: =AVERAGE(Q12:Z12) -> 1.902 | AC12: =(AA12/(AA12+'Cull Yield'!AA12))*100 -> 61.236317 | AF12: =(Q12/B12)*16 -> 0.89931034 | AG12: =(R12/C12)*16 -> 0.81655172 | AH12: =(S12/D12)*16 -> 0.81655172 | AI12: . | AJ12: . | AK12: . | AL12: . | AM12: . | AN12: . | AO12: . | AP12: =AVERAGE(AF12:AO12) -> 0.84413793
A13: UKYT-25-011 | B13: 40 | C13: 49 | D13: 51 | E13: . | F13: . | G13: . | H13: . | I13: . | J13: . | K13: . | L13: =SUM(B13:K13) -> 140 | M13: =AVERAGE(B13:K13) -> 46.666667 | N13: =(L13/(L13+'Cull Yield'!L13))*100 -> 69.651741 | Q13: 2.13 | R13: 2.65 | S13: 2.63 | T13: 4.84 | U13: 1.16 | V13: 1.18 | W13: 1.22 | X13: 0.62 | Y13: 1.74 | Z13: 2.41 | AA13: =SUM(Q13:Z13) -> 20.58 | AB13: =AVERAGE(Q13:Z13) -> 2.058 | AC13: =(AA13/(AA13+'Cull Yield'!AA13))*100 -> 65.562281 | AF13: =(Q13/B13)*16 -> 0.852 | AG13: =(R13/C13)*16 -> 0.86530612 | AH13: =(S13/D13)*16 -> 0.82509804 | AI13: . | AJ13: . | AK13: . | AL13: . | AM13: . | AN13: . | AO13: . | AP13: =AVERAGE(AF13:AO13) -> 0.84746805
A14: UKYT-25-012 | B14: 12 | C14: 104 | D14: 110 | E14: . | F14: . | G14: . | H14: . | I14: . | J14: . | L14: =SUM(B14:K14) -> 226 | M14: =AVERAGE(B14:K14) -> 75.333333 | N14: =(L14/(L14+'Cull Yield'!L14))*100 -> 94.957983 | Q14: 0.79 | R14: 5.36 | S14: 3.58 | T14: 4.86 | U14: 8.55 | V14: 5.13 | W14: 1.69 | X14: 0.91 | Y14: 2.62 | Z14: 3.35 | AA14: =SUM(Q14:Z14) -> 36.84 | AB14: =AVERAGE(Q14:Z14) -> 3.684 | AC14: =(AA14/(AA14+'Cull Yield'!AA14))*100 -> 82.972973 | AF14: =(Q14/B14)*16 -> 1.0533333 | AG14: =(R14/C14)*16 -> 0.82461538 | AH14: =(S14/D14)*16 -> 0.52072727 | AI14: . | AJ14: . | AK14: . | AL14: . | AM14: . | AN14: . | AO14: . | AP14: =AVERAGE(AF14:AO14) -> 0.79955866
A15: UKYT-25-013 | B15: 30 | C15: 127 | D15: 119 | E15: . | F15: . | G15: . | H15: . | I15: . | J15: . | K15: . | L15: =SUM(B15:K15) -> 276 | M15: =AVERAGE(B15:K15) -> 92 | N15: =(L15/(L15+'Cull Yield'!L15))*100 -> 87.898089 | Q15: 1.63 | R15: 6.11 | S15: 3.61 | T15: 5.62 | U15: 0.98 | V15: 6.13 | W15: 3.71 | X15: 0.66 | Y15: 3.63 | Z15: 1.76 | AA15: =SUM(Q15:Z15) -> 33.84 | AB15: =AVERAGE(Q15:Z15) -> 3.384 | AC15: =(AA15/(AA15+'Cull Yield'!AA15))*100 -> 82.819383 | AF15: =(Q15/B15)*16 -> 0.86933333 | AG15: =(R15/C15)*16 -> 0.76976378 | AH15: =(S15/D15)*16 -> 0.48537815 | AI15: . | AJ15: . | AK15: . | AL15: . | AM15: . | AN15: . | AO15: . | AP15: =AVERAGE(AF15:AO15) -> 0.70815842
A16: UKYT-25-014 | B16: 40 | C16: 176 | D16: 78 | E16: . | F16: . | G16: . | H16: . | I16: . | J16: . | K16: . | L16: =SUM(B16:K16) -> 294 | M16: =AVERAGE(B16:K16) -> 98 | N16: =(L16/(L16+'Cull Yield'!L16))*100 -> 92.163009 | Q16: 2.24 | R16: 6.48 | S16: 2.86 | T16: 6.89 | U16: 1.56 | V16: 4.16 | W16: 2.78 | X16: 1.36 | Y16: 3.33 | Z16: 1.6 | AA16: =SUM(Q16:Z16) -> 33.26 | AB16: =AVERAGE(Q16:Z16) -> 3.326 | AC16: =(AA16/(AA16+'Cull Yield'!AA16))*100 -> 74.092225 | AF16: =(Q16/B16)*16 -> 0.896 | AG16: =(R16/C16)*16 -> 0.58909091 | AH16: =(S16/D16)*16 -> 0.58666667 | AI16: . | AJ16: . | AK16: . | AL16: . | AM16: . | AN16: . | AO16: . | AP16: =AVERAGE(AF16:AO16) -> 0.69058586
A17: UKYT-25-015 | B17: . | C17: 2 | D17: 4 | E17: 1 | F17: 0 | G17: 0 | H17: 0 | I17: 3 | J17: 5 | K17: 0 | L17: =SUM(B17:K17) -> 15 | M17: =AVERAGE(B17:K17) -> 1.6666667 | N17: =(L17/(L17+'Cull Yield'!L17))*100 -> 37.5 | Q17: . | R17: 1.95 | S17: 1.65 | T17: 0.61 | U17: 0 | V17: 0 | W17: 0 | X17: 1.35 | Y17: 3.5 | Z17: 0 | AA17: =SUM(Q17:Z17) -> 9.06 | AB17: =AVERAGE(Q17:Z17) -> 1.0066667 | AC17: =(AA17/(AA17+'Cull Yield'!AA17))*100 -> 40.195209 | AF17: . | AG17: =(R17/C17)*16 -> 15.6 | AH17: =(S17/D17)*16 -> 6.6 | AI17: =(T17/E17)*16 -> 9.76 | AJ17: . | AK17: . | AL17: . | AM17: =(X17/I17)*16 -> 7.2 | AN17: =(Y17/J17)*16 -> 11.2 | AO17: . | AP17: =AVERAGE(AF17:AO17) -> 10.072
A18: UKYT-25-016 | B18: 1 | C18: 24 | D18: 17 | E18: . | F18: . | G18: . | H18: . | I18: . | J18: . | K18: . | L18: =SUM(B18:K18) -> 42 | M18: =AVERAGE(B18:K18) -> 14 | N18: =(L18/(L18+'Cull Yield'!L18))*100 -> 68.852459 | Q18: 0.03 | R18: 0.69 | S18: 0.34 | T18: 0.76 | U18: 0.16 | V18: 0.31 | W18: 1.13 | X18: 0.21 | Y18: 0.89 | Z18: 4.61 | AA18: =SUM(Q18:Z18) -> 9.13 | AB18: =AVERAGE(Q18:Z18) -> 0.913 | AC18: =(AA18/(AA18+'Cull Yield'!AA18))*100 -> 76.146789 | AF18: =(Q18/B18)*16 -> 0.48 | AG18: =(R18/C18)*16 -> 0.46 | AH18: =(S18/D18)*16 -> 0.32 | AI18: . | AJ18: . | AK18: . | AL18: . | AM18: . | AN18: . | AO18: . | AP18: =AVERAGE(AF18:AO18) -> 0.42
A19: UKYT-25-017 | B19: 18 | C19: 77 | D19: 26 | E19: . | F19: . | G19: . | H19: . | I19: . | J19: . | K19: . | L19: =SUM(B19:K19) -> 121 | M19: =AVERAGE(B19:K19) -> 40.333333 | N19: =(L19/(L19+'Cull Yield'!L19))*100 -> 81.756757 | Q19: 1.28 | R19: 5.36 | S19: 0.89 | T19: 7.29 | U19: 3 | V19: 2.05 | W19: 3.31 | X19: 2.08 | Y19: 4.28 | Z19: 3.93 | AA19: =SUM(Q19:Z19) -> 33.47 | AB19: =AVERAGE(Q19:Z19) -> 3.347 | AC19: =(AA19/(AA19+'Cull Yield'!AA19))*100 -> 78.200935 | AF19: =(Q19/B19)*16 -> 1.1377778 | AG19: =(R19/C19)*16 -> 1.1137662 | AH19: =(S19/D19)*16 -> 0.54769231 | AI19: . | AJ19: . | AK19: . | AL19: . | AM19: . | AN19: . | AO19: . | AP19: =AVERAGE(AF19:AO19) -> 0.93307877
A21: UKYT-26-006 | B21: 39 | C21: 151 | D21: 108 | E21: . | F21: . | G21: . | H21: . | I21: . | J21: . | K21: . | L21: =SUM(B21:K21) -> 298 | M21: =AVERAGE(B21:K21) -> 99.333333 | N21: =(L21/(L21+'Cull Yield'!L21))*100 -> 84.419263 | Q21: 1.95 | R21: 6.63 | S21: 3.41 | T21: 1.54 | U21: 0.56 | V21: 1.19 | W21: 0.55 | X21: 0.89 | Y21: 0.38 | Z21: 1.86 | AA21: =SUM(Q21:Z21) -> 18.96 | AB21: =AVERAGE(Q21:Z21) -> 1.896 | AC21: =(AA21/(AA21+'Cull Yield'!AA21))*100 -> 66.901905 | AF21: =(Q21/B21)*16 -> 0.8 | AG21: =(R21/C21)*16 -> 0.70251656 | AH21: =(S21/D21)*16 -> 0.50518519 | AI21: . | AJ21: . | AK21: . | AL21: . | AM21: . | AN21: . | AO21: . | AP21: =AVERAGE(AF21:AO21) -> 0.66923391
A22: UKYT-26-011 | B22: 0 | C22: 2 | D22: 1 | E22: 6 | F22: 1 | G22: 1 | H22: 0 | I22: 5 | J22: 0 | K22: 2 | L22: =SUM(B22:K22) -> 18 | M22: =AVERAGE(B22:K22) -> 1.8 | N22: =(L22/(L22+'Cull Yield'!L22))*100 -> 28.125 | Q22: 0 | R22: 1.35 | S22: 0.65 | T22: 2.16 | U22: 0.85 | V22: 0.85 | W22: 0 | X22: 3.05 | Y22: 0 | Z22: 0.35 | AA22: =SUM(Q22:Z22) -> 9.26 | AB22: =AVERAGE(Q22:Z22) -> 0.926 | AC22: =(AA22/(AA22+'Cull Yield'!AA22))*100 -> 23.330814 | AF22: . | AG22: =(R22/C22)*16 -> 10.8 | AH22: =(S22/D22)*16 -> 10.4 | AI22: =(T22/E22)*16 -> 5.76 | AJ22: =(U22/F22)*16 -> 13.6 | AK22: =(V22/G22)*16 -> 13.6 | AL22: . | AM22: =(X22/I22)*16 -> 9.76 | AN22: . | AO22: =(Z22/K22)*16 -> 2.8 | AP22: =AVERAGE(AF22:AO22) -> 9.5314286
A23: UKYT-26-012 | B23: 3 | C23: 0 | D23: 2 | E23: 8 | F23: 2 | G23: 1 | H23: 0 | I23: 1 | J23: 3 | K23: 4 | L23: =SUM(B23:K23) -> 24 | M23: =AVERAGE(B23:K23) -> 2.4 | N23: =(L23/(L23+'Cull Yield'!L23))*100 -> 41.37931 | Q23: 3.35 | R23: 0 | S23: 1.5 | T23: 2.44 | U23: 1.75 | V23: 0.7 | W23: 0 | X23: 0.15 | Y23: 1.55 | Z23: 2.4 | AA23: =SUM(Q23:Z23) -> 13.84 | AB23: =AVERAGE(Q23:Z23) -> 1.384 | AC23: =(AA23/(AA23+'Cull Yield'!AA23))*100 -> 36.808511 | AF23: =(Q23/B23)*16 -> 17.866667 | AG23: . | AH23: =(S23/D23)*16 -> 12 | AI23: =(T23/E23)*16 -> 4.88 | AJ23: =(U23/F23)*16 -> 14 | AK23: =(V23/G23)*16 -> 11.2 | AL23: . | AM23: =(X23/I23)*16 -> 2.4 | AN23: =(Y23/J23)*16 -> 8.2666667 | AO23: =(Z23/K23)*16 -> 9.6 | AP23: =AVERAGE(AF23:AO23) -> 10.026667
A24: UKYT-26-013 | B24: 1 | C24: 3 | D24: 1 | E24: 1 | F24: 6 | G24: 12 | H24: 2 | I24: 5 | J24: 17 | K24: 10 | L24: =SUM(B24:K24) -> 58 | M24: =AVERAGE(B24:K24) -> 5.8 | N24: =(L24/(L24+'Cull Yield'!L24))*100 -> 58.585859 | Q24: 1.05 | R24: 2.4 | S24: 0.65 | T24: 0.38 | U24: 3.9 | V24: 6.,45 | W24: 0.75 | X24: 1.85 | Y24: 6.85 | Z24: 3.75 | AA24: =SUM(Q24:Z24) -> 21.58 | AB24: =AVERAGE(Q24:Z24) -> 2.3977778 | AC24: =(AA24/(AA24+'Cull Yield'!AA24))*100 -> 53.468781 | AF24: =(Q24/B24)*16 -> 16.8 | AG24: =(R24/C24)*16 -> 12.8 | AH24: =(S24/D24)*16 -> 10.4 | AI24: =(T24/E24)*16 -> 6.08 | AJ24: =(U24/F24)*16 -> 10.4 | AK24: . | AL24: =(W24/H24)*16 -> 6 | AM24: =(X24/I24)*16 -> 5.92 | AN24: =(Y24/J24)*16 -> 6.4470588 | AO24: =(Z24/K24)*16 -> 6 | AP24: =AVERAGE(AF24:AO24) -> 8.9830065
A25: UKYT-26-020 | B25: . | C25: 1 | D25: 3 | E25: 18 | F25: 0 | G25: 0 | H25: 0 | I25: 0 | J25: 4 | K25: 0 | L25: =SUM(B25:K25) -> 26 | M25: =AVERAGE(B25:K25) -> 2.8888889 | N25: =(L25/(L25+'Cull Yield'!L25))*100 -> 43.333333 | Q25: . | R25: 1.05 | S25: 1.65 | T25: 6.48 | U25: 0 | V25: 0 | W25: 0 | X25: 0 | Y25: 2.85 | Z25: 0 | AA25: =SUM(Q25:Z25) -> 12.03 | AB25: =AVERAGE(Q25:Z25) -> 1.3366667 | AC25: =(AA25/(AA25+'Cull Yield'!AA25))*100 -> 41.843478 | AF25: . | AG25: =(R25/C25)*16 -> 16.8 | AH25: =(S25/D25)*16 -> 8.8 | AI25: =(T25/E25)*16 -> 5.76 | AJ25: . | AK25: . | AL25: . | AM25: . | AN25: =(Y25/J25)*16 -> 11.4 | AO25: . | AP25: =AVERAGE(AF25:AO25) -> 10.69
A26: UKYT-26-021 | B26: 0 | C26: 2 | D26: 5 | E26: 14 | F26: 2 | G26: 0 | H26: 0 | I26: 0 | J26: 2 | K26: 0 | L26: =SUM(B26:K26) -> 25 | M26: =AVERAGE(B26:K26) -> 2.5 | N26: =(L26/(L26+'Cull Yield'!L26))*100 -> 37.878788 | Q26: 0 | R26: 0.85 | S26: 4.85 | T26: 3.75 | U26: 1.45 | V26: 0 | W26: 0 | X26: 0 | Y26: 1.55 | Z26: 0 | AA26: =SUM(Q26:Z26) -> 12.45 | AB26: =AVERAGE(Q26:Z26) -> 1.245 | AC26: =(AA26/(AA26+'Cull Yield'!AA26))*100 -> 35.714286 | AF26: . | AG26: =(R26/C26)*16 -> 6.8 | AH26: =(S26/D26)*16 -> 15.52 | AI26: =(T26/E26)*16 -> 4.2857143 | AJ26: =(U26/F26)*16 -> 11.6 | AK26: . | AL26: . | AM26: . | AN26: =(Y26/J26)*16 -> 12.4 | AO26: . | AP26: =AVERAGE(AF26:AO26) -> 10.121143
A27: UKYT-26-022 | B27: . | C27: 0 | D27: 4 | E27: 1 | F27: 1 | G27: 0 | H27: 0 | I27: 7 | J27: 8 | K27: 0 | L27: =SUM(B27:K27) -> 21 | M27: =AVERAGE(B27:K27) -> 2.3333333 | N27: =(L27/(L27+'Cull Yield'!L27))*100 -> 32.8125 | Q27: . | R27: 0 | S27: 2.75 | T27: 0.2 | U27: 0.65 | V27: 0 | W27: 0 | X27: 2.85 | Y27: 3.1 | Z27: 0 | AA27: =SUM(Q27:Z27) -> 9.55 | AB27: =AVERAGE(Q27:Z27) -> 1.0611111 | AC27: =(AA27/(AA27+'Cull Yield'!AA27))*100 -> 33.252089 | AF27: . | AG27: . | AH27: =(S27/D27)*16 -> 11 | AI27: =(T27/E27)*16 -> 3.2 | AJ27: =(U27/F27)*16 -> 10.4 | AK27: . | AL27: . | AM27: =(X27/I27)*16 -> 6.5142857 | AN27: =(Y27/J27)*16 -> 6.2 | AO27: . | AP27: =AVERAGE(AF27:AO27) -> 7.4628571
A28: UKYT-26-023 | B28: 1 | C28: 6 | D28: 9 | E28: 24 | F28: 5 | G28: 0 | H28: 2 | I28: 5 | J28: 13 | K28: 4 | L28: =SUM(B28:K28) -> 69 | M28: =AVERAGE(B28:K28) -> 6.9 | N28: =(L28/(L28+'Cull Yield'!L28))*100 -> 62.727273 | Q28: 0.8 | R28: 4.15 | S28: 5.65 | T28: 6.8 | U28: 3.25 | V28: 0 | W28: 0.7 | X28: 1.8 | Y28: 5.2 | Z28: 1.25 | AA28: =SUM(Q28:Z28) -> 29.6 | AB28: =AVERAGE(Q28:Z28) -> 2.96 | AC28: =(AA28/(AA28+'Cull Yield'!AA28))*100 -> 59.919028 | AF28: =(Q28/B28)*16 -> 12.8 | AG28: =(R28/C28)*16 -> 11.066667 | AH28: =(S28/D28)*16 -> 10.044444 | AI28: =(T28/E28)*16 -> 4.5333333 | AJ28: =(U28/F28)*16 -> 10.4 | AK28: . | AL28: =(W28/H28)*16 -> 5.6 | AM28: =(X28/I28)*16 -> 5.76 | AN28: =(Y28/J28)*16 -> 6.4 | AO28: =(Z28/K28)*16 -> 5 | AP28: =AVERAGE(AF28:AO28) -> 7.9560494
A29: UKYT-26-024 | B29: . | C29: 1 | D29: 1 | E29: . | F29: 1 | G29: 0 | H29: 0 | I29: 0 | J29: 0 | K29: 0 | L29: =SUM(B29:K29) -> 3 | M29: =AVERAGE(B29:K29) -> 0.375 | N29: =(L29/(L29+'Cull Yield'!L29))*100 -> 3.9473684 | Q29: . | R29: 0.65 | S29: 0.8 | T29: . | U29: 1.25 | V29: 0 | W29: 0 | X29: 0 | Y29: 0 | Z29: 0 | AA29: =SUM(Q29:Z29) -> 2.7 | AB29: =AVERAGE(Q29:Z29) -> 0.3375 | AC29: =(AA29/(AA29+'Cull Yield'!AA29))*100 -> 7.1240106 | AF29: . | AG29: =(R29/C29)*16 -> 10.4 | AH29: =(S29/D29)*16 -> 12.8 | AI29: . | AJ29: =(U29/F29)*16 -> 20 | AK29: . | AL29: . | AM29: . | AN29: . | AO29: . | AP29: =AVERAGE(AF29:AO29) -> 14.4
A30: UKYT-26-025 | B30: . | C30: 0 | D30: 1 | E30: 7 | F30: 3 | G30: 0 | H30: 3 | I30: 12 | J30: 12 | K30: 0 | L30: =SUM(B30:K30) -> 38 | M30: =AVERAGE(B30:K30) -> 4.2222222 | N30: =(L30/(L30+'Cull Yield'!L30))*100 -> 34.545455 | Q30: . | R30: 0 | S30: 0.95 | T30: 5.35 | U30: 0.95 | V30: 0 | W30: 0.85 | X30: 5.2 | Y30: 4.45 | Z30: 0 | AA30: =SUM(Q30:Z30) -> 17.75 | AB30: =AVERAGE(Q30:Z30) -> 1.9722222 | AC30: =(AA30/(AA30+'Cull Yield'!AA30))*100 -> 42.874396 | AF30: . | AG30: . | AH30: =(S30/D30)*16 -> 15.2 | AI30: =(T30/E30)*16 -> 12.228571 | AJ30: =(U30/F30)*16 -> 5.0666667 | AK30: . | AL30: =(W30/H30)*16 -> 4.5333333 | AM30: =(X30/I30)*16 -> 6.9333333 | AN30: =(Y30/J30)*16 -> 5.9333333 | AO30: . | AP30: =AVERAGE(AF30:AO30) -> 8.315873
A31: UKYT-26-026 | B31: 0 | C31: 0 | D31: 4 | E31: 3 | F31: 0 | G31: 0 | H31: 0 | I31: 1 | J31: 0 | K31: 0 | L31: =SUM(B31:K31) -> 8 | M31: =AVERAGE(B31:K31) -> 0.8 | N31: =(L31/(L31+'Cull Yield'!L31))*100 -> 12.698413 | Q31: 0 | R31: 0 | S31: 3.2 | T31: 2.05 | U31: 0 | V31: 0 | W31: 0 | X31: 0.45 | Y31: 0 | Z31: 0 | AA31: =SUM(Q31:Z31) -> 5.7 | AB31: =AVERAGE(Q31:Z31) -> 0.57 | AC31: =(AA31/(AA31+'Cull Yield'!AA31))*100 -> 13.953488 | AF31: . | AG31: . | AH31: =(S31/D31)*16 -> 12.8 | AI31: =(T31/E31)*16 -> 10.933333 | AJ31: . | AK31: . | AL31: . | AM31: =(X31/I31)*16 -> 7.2 | AN31: . | AO31: . | AP31: =AVERAGE(AF31:AO31) -> 10.311111
A32: UKYT-26-027 | B32: . | C32: 0 | D32: 9 | E32: 12 | F32: 4 | G32: 1 | H32: 1 | I32: 3 | J32: 2 | K32: 3 | L32: =SUM(B32:K32) -> 35 | M32: =AVERAGE(B32:K32) -> 3.8888889 | N32: =(L32/(L32+'Cull Yield'!L32))*100 -> 50 | Q32: . | R32: 0 | S32: 9.65 | T32: 9.05 | U32: 3.3 | V32: 0.85 | W32: 0.8 | X32: 1.35 | Y32: 1.1 | Z32: 1.2 | AA32: =SUM(Q32:Z32) -> 27.3 | AB32: =AVERAGE(Q32:Z32) -> 3.0333333 | AC32: =(AA32/(AA32+'Cull Yield'!AA32))*100 -> 51.851852 | AF32: . | AG32: . | AH32: =(S32/D32)*16 -> 17.155556 | AI32: =(T32/E32)*16 -> 12.066667 | AJ32: =(U32/F32)*16 -> 13.2 | AK32: =(V32/G32)*16 -> 13.6 | AL32: =(W32/H32)*16 -> 12.8 | AM32: =(X32/I32)*16 -> 7.2 | AN32: =(Y32/J32)*16 -> 8.8 | AO32: =(Z32/K32)*16 -> 6.4 | AP32: =AVERAGE(AF32:AO32) -> 11.402778
A33: UKYT-26-028 | B33: 3 | C33: 8 | D33: 4 | E33: 16 | F33: 4 | G33: 3 | H33: 0 | I33: 4 | J33: 6 | K33: 8 | L33: =SUM(B33:K33) -> 56 | M33: =AVERAGE(B33:K33) -> 5.6 | N33: =(L33/(L33+'Cull Yield'!L33))*100 -> 60.215054 | Q33: 2.2 | R33: 5.6 | S33: 1.65 | T33: 8.95 | U33: 1.75 | V33: 2.25 | W33: 0 | X33: 1.7 | Y33: 2.3 | Z33: 3.85 | AA33: =SUM(Q33:Z33) -> 30.25 | AB33: =AVERAGE(Q33:Z33) -> 3.025 | AC33: =(AA33/(AA33+'Cull Yield'!AA33))*100 -> 63.617245 | AF33: =(Q33/B33)*16 -> 11.733333 | AG33: =(R33/C33)*16 -> 11.2 | AH33: =(S33/D33)*16 -> 6.6 | AI33: =(T33/E33)*16 -> 8.95 | AJ33: =(U33/F33)*16 -> 7 | AK33: =(V33/G33)*16 -> 12 | AL33: . | AM33: =(X33/I33)*16 -> 6.8 | AN33: =(Y33/J33)*16 -> 6.1333333 | AO33: =(Z33/K33)*16 -> 7.7 | AP33: =AVERAGE(AF33:AO33) -> 8.6796296
A34: UKYT-26-029 | B34: 1 | C34: 9 | D34: 7 | E34: 42 | F34: 26 | G34: 11 | H34: 5 | I34: 8 | J34: 16 | K34: 7 | L34: =SUM(B34:K34) -> 132 | M34: =AVERAGE(B34:K34) -> 13.2 | N34: =(L34/(L34+'Cull Yield'!L34))*100 -> 58.666667 | Q34: 0.5 | R34: 3.15 | S34: 2.9 | T34: 14.75 | U34: 8.7 | V34: 2.8 | W34: 1.35 | X34: 2.25 | Y34: 3.65 | Z34: 1.7 | AA34: =SUM(Q34:Z34) -> 41.75 | AB34: =AVERAGE(Q34:Z34) -> 4.175 | AC34: =(AA34/(AA34+'Cull Yield'!AA34))*100 -> 63.886764 | AF34: =(Q34/B34)*16 -> 8 | AG34: =(R34/C34)*16 -> 5.6 | AH34: =(S34/D34)*16 -> 6.6285714 | AI34: =(T34/E34)*16 -> 5.6190476 | AJ34: =(U34/F34)*16 -> 5.3538462 | AK34: =(V34/G34)*16 -> 4.0727273 | AL34: =(W34/H34)*16 -> 4.32 | AM34: =(X34/I34)*16 -> 4.5 | ... AO34: =(Z34/K34)*16 -> 3.8857143 | AP34: =AVERAGE(AF34:AO34) -> 5.1629907
A35: UKYT-26-030 | B35: 1 | C35: 8 | D35: 21 | E35: 37 | F35: 27 | G35: 6 | H35: 3 | I35: 0 | J35: 3 | K35: 0 | L35: =SUM(B35:K35) -> 106 | M35: =AVERAGE(B35:K35) -> 10.6 | N35: =(L35/(L35+'Cull Yield'!L35))*100 -> 44.166667 | Q35: 0.3 | R35: 1.85 | S35: 4.35 | T35: 8.25 | U35: 4.9 | V35: 0.9 | W35: 0.45 | X35: 0 | Y35: 0.5 | Z35: 0 | AA35: =SUM(Q35:Z35) -> 21.5 | AB35: =AVERAGE(Q35:Z35) -> 2.15 | AC35: =(AA35/(AA35+'Cull Yield'!AA35))*100 -> 52.247874 | AF35: =(Q35/B35)*16 -> 4.8 | AG35: =(R35/C35)*16 -> 3.7 | AH35: =(S35/D35)*16 -> 3.3142857 | AI35: =(T35/E35)*16 -> 3.5675676 | AJ35: =(U35/F35)*16 -> 2.9037037 | AK35: =(V35/G35)*16 -> 2.4 | AL35: =(W35/H35)*16 -> 2.4 | AM35: . | AN35: =(Y35/J35)*16 -> 2.6666667 | AO35: . | AP35: =AVERAGE(AF35:AO35) -> 3.219028
A36: UKYT-26-031 | B36: 2 | C36: 5 | D36: 23 | E36: 15 | F36: 13 | G36: 7 | H36: 7 | I36: 3 | J36: 1 | K36: 18 | L36: =SUM(B36:K36) -> 94 | M36: =AVERAGE(B36:K36) -> 9.4 | N36: =(L36/(L36+'Cull Yield'!L36))*100 -> 41.777778 | Q36: 0.85 | R36: 2.1 | S36: 9.55 | T36: 6.1 | U36: 5.1 | V36: 1.95 | W36: 1.95 | X36: 0.95 | Y36: 0.1 | Z36: 3.1 | AA36: =SUM(Q36:Z36) -> 31.75 | AB36: =AVERAGE(Q36:Z36) -> 3.175 | AC36: =(AA36/(AA36+'Cull Yield'!AA36))*100 -> 51.045016 | AF36: =(Q36/B36)*16 -> 6.8 | AG36: =(R36/C36)*16 -> 6.72 | AH36: =(S36/D36)*16 -> 6.6434783 | AI36: =(T36/E36)*16 -> 6.5066667 | AJ36: =(U36/F36)*16 -> 6.2769231 | AK36: =(V36/G36)*16 -> 4.4571429 | AL36: =(W36/H36)*16 -> 4.4571429 | AM36: =(X36/I36)*16 -> 5.0666667 | ... AO36: =(Z36/K36)*16 -> 2.7555556 | AP36: =AVERAGE(AF36:AO36) -> 5.1283576
A38: Cherokee Purple | B38: 2 | C38: 2 | D38: 2 | E38: 1 | F38: 0 | G38: 0 | H38: 0 | I38: 0 | J38: 0 | K38: 0 | L38: =SUM(B38:K38) -> 7 | M38: =AVERAGE(B38:K38) -> 0.7 | N38: =(L38/(L38+'Cull Yield'!L38))*100 -> 9.4594595 | Q38: 1.35 | R38: 0.9 | S38: 1.15 | T38: 0.26 | U38: 0 | V38: 0 | W38: 0 | X38: 0 | Y38: 0 | Z38: 0 | AA38: =SUM(Q38:Z38) -> 3.66 | AB38: =AVERAGE(Q38:Z38) -> 0.366 | AC38: =(AA38/(AA38+'Cull Yield'!AA38))*100 -> 9.3272171 | AF38: =(Q38/B38)*16 -> 10.8 | AG38: =(R38/C38)*16 -> 7.2 | AH38: =(S38/D38)*16 -> 9.2 | AI38: =(T38/E38)*16 -> 4.16 | AJ38: . | AK38: . | AL38: . | AM38: . | AN38: . | AO38: . | AP38: =AVERAGE(AF38:AO38) -> 7.84
A39: UKYT-26-033 | B39: 3 | C39: 38 | D39: 19 | E39: 15 | F39: 6 | G39: 1 | H39: 8 | I39: 10 | J39: 8 | K39: 4 | L39: =SUM(B39:K39) -> 112 | M39: =AVERAGE(B39:K39) -> 11.2 | N39: =(L39/(L39+'Cull Yield'!L39))*100 -> 58.333333 | Q39: 1.45 | R39: 9.75 | S39: 4.9 | T39: 2.04 | U39: 1.9 | V39: 0.3 | W39: 2.3 | X39: 2.75 | Y39: 1.7 | Z39: 0.65 | AA39: =SUM(Q39:Z39) -> 27.74 | AB39: =AVERAGE(Q39:Z39) -> 2.774 | AC39: =(AA39/(AA39+'Cull Yield'!AA39))*100 -> 61.781737 | AF39: =(Q39/B39)*16 -> 7.7333333 | AG39: =(R39/C39)*16 -> 4.1052632 | AH39: =(S39/D39)*16 -> 4.1263158 | AI39: =(T39/E39)*16 -> 2.176 | AJ39: =(U39/F39)*16 -> 5.0666667 | AK39: =(V39/G39)*16 -> 4.8 | AL39: =(W39/H39)*16 -> 4.6 | AM39: =(X39/I39)*16 -> 4.4 | ... AO39: =(Z39/K39)*16 -> 2.6 | AP39: =AVERAGE(AF39:AO39) -> 4.3007579
